Workbook
Name category_ids: #REF!

Sheet 評価レポート
A3: SARMS 京セラ Aof 成果レポート
A6: メンバー情報
B8: 氏名 | F8: Ponpich (Aof)
B9: 加入 | F9: 2016/05/03 ~
B10: ポジション | F10: プログラマー
A13: 成果概要
B15: プロジェクト名 | G15: SARMS 京セラ
B16: 改修件数 | G16: 31件
B17: 差し戻し件数 | G17: 7件
C18: - 仕様とは異なる条件になっていた
C19: - バリデーションが正常に修正されていなかった
C20: - スペースが揃っていない
C21: - SQLエラーが表示されていた
C22: - Functionを使用するようにリファクタリングしたため
A25: SARMS スキルカバレッジ
B27: カテゴリ | H27: 詳細 | Q27: カテゴリID | T27: 件数 | X27: フリーテキスト（エンジニア） | AI27: フリーテキスト（マネージャー）
B28: ハードウェア台帳 | H28: 一覧 | Q28: Hl | T28: =IF(COUNTIF(改修詳細!E:E,Q28)=0,"-",COUNTIF(改修詳細!E:E,Q28)) -> 2 | X28: コードに対するにコメントが多い。
H29: 新規登録 | Q29: Hn | T29: =IF(COUNTIF(改修詳細!E:E,Q29)=0,"-",COUNTIF(改修詳細!E:E,Q29)) -> 5 | X29: 構造が複雑。
H30: 更新 | Q30: He | T30: =IF(COUNTIF(改修詳細!E:E,Q30)=0,"-",COUNTIF(改修詳細!E:E,Q30)) -> 2 | X30: 最初は構造に混乱したが理解できた。
H31: 保守 | Q31: He | T31: =IF(COUNTIF(改修詳細!E:E,Q31)=0,"-",COUNTIF(改修詳細!E:E,Q31)) -> 2 | X31: ARMSに入社して最初に携わったコードだから思いれが深い。 | AI31: ARMSに入社する前に比べると格段にコーディング力が上昇したと思う
H32: 削除 | Q32: Hd | T32: =IF(COUNTIF(改修詳細!E:E,Q32)=0,"-",COUNTIF(改修詳細!E:E,Q32)) -> 2 | X32: 最初はDAOの改修で躓いたが今ではとても良い機能だと思う | AI32: DAOの改修は入社早々で大変だったと思う、それにしたらよくSQLエラーも起きずに機能しているし素晴らしい
H33: バリデーション | Q33: Hv | T33: =IF(COUNTIF(改修詳細!E:E,Q33)=0,"-",COUNTIF(改修詳細!E:E,Q33)) -> 4 | X33: コメントが多すぎて読みづらかった
B34: ソフトウェア台帳 | H34: 一覧 | Q34: Sl | T34: =IF(COUNTIF(改修詳細!E:E,Q34)=0,"-",COUNTIF(改修詳細!E:E,Q34)) -> - | X34: -
H35: 新規登録 | Q35: Sn | T35: =IF(COUNTIF(改修詳細!E:E,Q35)=0,"-",COUNTIF(改修詳細!E:E,Q35)) -> 1 | X35: 読みやすくするためにコメントを減らす必要がありそう
H36: 更新 | Q36: Se | T36: =IF(COUNTIF(改修詳細!E:E,Q36)=0,"-",COUNTIF(改修詳細!E:E,Q36)) -> - | X36: -
H37: 保守 | Q37: Se | T37: =IF(COUNTIF(改修詳細!E:E,Q37)=0,"-",COUNTIF(改修詳細!E:E,Q37)) -> - | X37: -
H38: 削除 | Q38: Sd | T38: =IF(COUNTIF(改修詳細!E:E,Q38)=0,"-",COUNTIF(改修詳細!E:E,Q38)) -> - | X38: -
H39: バリデーション | Q39: Sv | T39: =IF(COUNTIF(改修詳細!E:E,Q39)=0,"-",COUNTIF(改修詳細!E:E,Q39)) -> - | X39: -
B40: ライセンス台帳 | H40: 一覧 | Q40: Ll | T40: =IF(COUNTIF(改修詳細!E:E,Q40)=0,"-",COUNTIF(改修詳細!E:E,Q40)) -> 2 | X40: コードが読みやすい
H41: 新規登録 | Q41: Ln | T41: =IF(COUNTIF(改修詳細!E:E,Q41)=0,"-",COUNTIF(改修詳細!E:E,Q41)) -> - | X41: -
H42: 更新 | Q42: Le | T42: =IF(COUNTIF(改修詳細!E:E,Q42)=0,"-",COUNTIF(改修詳細!E:E,Q42)) -> - | X42: -
H43: 保守 | Q43: Le | T43: =IF(COUNTIF(改修詳細!E:E,Q43)=0,"-",COUNTIF(改修詳細!E:E,Q43)) -> - | X43: -
H44: 削除 | Q44: Ld | T44: =IF(COUNTIF(改修詳細!E:E,Q44)=0,"-",COUNTIF(改修詳細!E:E,Q44)) -> 1 | X44: DAOのおかげでコードが書きやすい
H45: バリデーション | Q45: Lv | T45: =IF(COUNTIF(改修詳細!E:E,Q45)=0,"-",COUNTIF(改修詳細!E:E,Q45)) -> - | X45: -
B46: ライセンス辞書 | H46: 一覧 | Q46: LDl | T46: =IF(COUNTIF(改修詳細!E:E,Q46)=0,"-",COUNTIF(改修詳細!E:E,Q46)) -> 1 | X46: 理解するのは難しくない
H47: 新規登録 | Q47: LDn | T47: =IF(COUNTIF(改修詳細!E:E,Q47)=0,"-",COUNTIF(改修詳細!E:E,Q47)) -> 2 | X47: コードが読みやすく理解しやすい
H48: 更新 | Q48: LDu | T48: =IF(COUNTIF(改修詳細!E:E,Q48)=0,"-",COUNTIF(改修詳細!E:E,Q48)) -> - | X48: -
H49: 保守 | Q49: LDe | T49: =IF(COUNTIF(改修詳細!E:E,Q49)=0,"-",COUNTIF(改修詳細!E:E,Q49)) -> 1 | X49: 潔い、理解しやすい
H50: 削除 | Q50: LDd | T50: =IF(COUNTIF(改修詳細!E:E,Q50)=0,"-",COUNTIF(改修詳細!E:E,Q50)) -> - | X50: -
H51: バリデーション | Q51: LDv | T51: =IF(COUNTIF(改修詳細!E:E,Q51)=0,"-",COUNTIF(改修詳細!E:E,Q51)) -> - | X51: -
...

Sheet 改修詳細
A1: No | B1: マージID | C1: モジュール名 | D1: 機能名 | E1: カテゴリID | F1: 難易度 | G1: タイトル | H1: 改修日付 | I1: 予定工数 | J1: 工数実績 | K1: Story | L1: タスクNo. | M1: 差し戻し理由
A2: 1 | B2: - | C2: インポート | D2: ライセンス辞書 更新 | E2: IMPld | F2: 3 | G2: インポート ライセンス辞書 更新 バリデーション 「辞書コード」存在チェック (002-004) | H2: 42629 | I2: - | J2: 6 | K2: #10490 | L2: #10922 | M2: -
A3: 2 | B3: - | C3: 収集情報 | D3: バリデーション | E3: INVn | F3: 4 | G3: ハードウェア管理番号同期処理（収集情報取込バッチ） | H3: 42605 | I3: 8 | J3: 5 | K3: #10285 | L3: #10476 | M3: 必要の無い処理の記述 「京セラではハードウェア管理番号の代わりに収集情報主キーを使用するがハードウェア管理番号を使用していた」
A4: 3 | B4: - | C4: ハードウェア台帳 | D4: バリデーション | E4: Hv | F4: 3 | G4: 一般ユーザログイン 同一のハードウェア管理番号が複数存在する場合にエラーメッセージを出力 | H4: 42593 | I4: 8 | J4: 6 | K4: #10392 | L4: #10398 | M4: -
A5: 4 | B5: - | C5: ハードウェア台帳 | D5: 更新 | E5: Hu | F5: 1 | G5: 一般ユーザ ハードウェア台帳 更新画面 説明ボタン配置の修正 | H5: 42592 | I5: 1 | J5: 1 | K5: #10392 | L5: #10393 | M5: -
A6: 5 | B6: - | C6: ライセンス台帳 | D6: 削除 | E6: Ld | F6: 3 | G6: [#213]ライセンス台帳 削除 削除しようとしたライセンスがアップグレード元の場合はエラーで止める | H6: 42590 | I6: 4 | J6: 3 | K6: #10345 | L6: #10367 | M6: -
A7: 6 | B7: - | C7: ライセンス割当 | D7: 検索 | E7: Ll | F7: 2 | G7: [#210]ライセンス割当 ライセンス台帳選択モーダル 検索オプション「廃棄済みライセンスを表示しない」は削除 | H7: 42590 | I7: 2 | J7: 1 | K7: #10345 | L7: #10387 | M7: -
A8: 7 | B8: - | C8: ライセンス割当 | D8: 登録 | E8: Sn | F8: 1 | G8: [#175,#209]ライセンス割当 新規登録・更新・ライセンス選択モーダル 文言修正 | H8: 42587 | I8: 8 | J8: 6 | K8: #10324 | L8: #10325 | M8: -
A9: 8 | B9: - | C9: ハードウェア台帳 | D9: 登録 | E9: Hn | F9: 2 | G9: [#194] ハードウェア台帳 新規登録・更新・インポート 文字数チェック修正 | H9: 42587 | I9: 2 | J9: 2 | K9: #10340 | L9: #10357 | M9: インデントが整ってない
A10: 9 | B10: - | C10: ライセンス辞書 | D10: 登録 | E10: LDn | F10: 3 | G10: ライセンス辞書 申請時 メール送信・文言適用 | H10: 42580 | I10: 4 | J10: 5 | K10: #10312 | L10: #10315 | M10: メールタイトル/文言の変更忘れ
A11: 10 | B11: - | C11: ライセンス辞書 | D11: 保守 | E11: LDe | F11: 2 | G11: ライセンス辞書 保守 upd_name, upd_syozoku のバリデーション削除 | H11: 42580 | I11: 1 | J11: 1 | K11: #10312 | L11: #10319 | M11: -
A12: 11 | B12: - | C12: ライセンス辞書 | D12: 登録 | E12: LDn | F12: 1 | G12: ライセンス辞書 新規申請 ページ最下部「一覧に戻る」へのリンク修正 | H12: 42573 | I12: 1 | J12: 1 | K12: #10285 | L12: #10305 | M12: -
A13: 12 | B13: - | C13: ハードウェア台帳 | D13: 更新 | E13: Hu | F13: 3 | G13: ハードウェア台帳 更新できない項目が存在する | H13: 42566 | I13: 1 | J13: 3 | K13: #10276 | L13: #10277 | M13: -
A14: 13 | B14: - | C14: ハードウェア台帳 | D14: 登録 | E14: Hn | F14: 2 | G14: ハードウェア台帳 「参照用使用者情報」項目の修正 | H14: 42559 | I14: 4 | J14: 5 | K14: #10159 | L14: #10160 | M14: -
A15: 14 | B15: - | C15: ライセンス台帳 | D15: 一覧 | E15: Ll | F15: 3 | G15: ライセンス台帳一覧 検索 と等しいの条件が動作しない不具合修正 | H15: 42559 | I15: - | J15: 3 | K15: #10159 | L15: #10239 | M15: -
A16: 15 | B16: - | C16: ライセンス辞書 | D16: 一覧 | E16: LDl | F16: 2 | G16: ライセンス辞書 一覧 検索項目の「ハードウェア固定」と「アップグレード版」が逆 | H16: 42559 | I16: 1 | J16: 1 | K16: #10159 | L16: #10218 | M16: -
A17: 16 | B17: - | C17: インポート | D17: ライセンス台帳 | E17: IMPl | F17: 3 | G17: インポート ライセンス台帳 バリデーション CSV項目基本設計書に従ったメンテナンス | H17: 42557 | I17: 8 | J17: 7 | K17: #9985 | L17: #9987 | M17: バリデーションが表示されてないように修正を加えたがバリデーションが表示されていた
A18: 17 | B18: - | C18: ハードウェア台帳 | D18: 登録 | E18: Hn | F18: 2 | G18: ハードウェア台帳「使用者によるソフトウェア追加導入削除コード(シ)」項目の入力必須可 | H18: 42555 | I18: 2 | J18: 2 | K18: #10079 | L18: #10163 | M18: -
A19: 18 | B19: - | C19: ハードウェア台帳 | D19: バリデーション | E19: Hv | F19: 2 | G19: ハードウェア台帳 バリデーション 軽微な修正 SARMS京セラ_バリデーション定義書に従ったメンテナンス | H19: 42545 | I19: 4 | J19: 3 | K19: #9943 | L19: #10018 | M19: -
A20: 19 | B20: - | C20: ライブラリ系 | D20: DAO | E20: LIVd | F20: 4 | G20: DAO関数改修 不要コード削除 | H20: 42545 | J20: 8 | K20: #10074 | L20: #10075#10076 | M20: SQLエラーが表示されていたため
A21: 20 | B21: - | C21: ハードウェア台帳 | D21: バリデーション | E21: Hv | F21: 2 | G21: ハードウェア台帳 バリデーション 軽微な修正 | H21: 42544 | I21: 4 | J21: 3 | K21: #9943 | L21: #10018 | M21: Function を使用するようにリファクタリングのため
A22: 21 | B22: - | C22: ハードウェア台帳 | D22: 削除 | E22: Hd | F22: 2 | G22: ハードウェア台帳 削除 削除完了時の追加実装 | H22: 42538 | I22: 4 | J22: 4 | K22: #9943 | L22: #9945 | M22: -
A23: 22 | B23: - | C23: ハードウェア台帳 | D23: 更新 | E23: He | F23: 2 | G23: 一般ユーザ編集画面修正 | H23: - | I23: - | J23: 4 | K23: - | L23: - | M23: -
A24: 23 | B24: - | C24: ハードウェア台帳 | D24: 登録 | E24: Hn | F24: 2 | G24: 収集情報手段の修正 | H24: - | I24: - | J24: 4 | K24: - | L24: - | M24: -
A25: 24 | B25: - | C25: ハードウェア台帳 | D25: バリデーション | E25: Hv | F25: 2 | G25: ハードウェア台帳 収集情報更新 バリデーション SARMS京セラ_バリデーション定義書に従ったメンテナンス | H25: - | I25: 2 | J25: 4 | K25: #9943 | L25: #9911 | M25: 改修箇所への署名忘れ
A26: 25 | B26: - | C26: ハードウェア台帳 | D26: 登録 | E26: Hn | F26: 2 | G26: ハードウェア台帳 新規登録 手動登録時の「情報収集手段」の内容を「手動登録」に変更 | H26: - | I26: 2 | J26: 2 | K26: #9943 | L26: #9953 | M26: -
A27: 26 | B27: - | C27: ハードウェア台帳 | D27: 一覧 | E27: Hl | F27: 2 | G27: ハードウェア台帳 CSV出力 「資産管理グループ内部キー(収)」を「資産管理グループコード」に変更 | H27: - | I27: 2 | J27: 5 | K27: #9943 | L27: #9954 | M27: -
A28: 27 | B28: - | C28: ハードウェア台帳 | D28: 削除 | E28: Hd | F28: 4 | G28: ハードウェア台帳 削除 削除完了時の追加実装 ハードウェア台帳に紐づくデータも削除する様に修正 | H28: - | I28: 4 | J28: 7 | K28: #9943 | L28: #9945 | M28: -
A29: 28 | B29: - | C29: ハードウェア台帳 | D29: 更新 | E29: Hu | F29: 4 | G29: ハードウェア台帳 更新 所属変更時の警告とライセンス割当解除処理 | H29: - | I29: 4 | J29: 6 | K29: #9943 | L29: #9950 | M29: -
A30: 29 | B30: - | C30: ハードウェア台帳 | D30: 一覧 | E30: Hl | F30: 2 | G30: ハードウェア台帳一覧 修正 一覧項目のメンテナンス | H30: - | I30: - | J30: 8 | K30: #9892 | L30: #9956 | M30: -
A31: 30 | B31: - | C31: ユーザ | D31: 登録 | E31: Un | F31: 1 | G31: IT資産管理者 「代表者社員番号」(メールアドレス) 項目をテキストエリアからテキストボックスに修正 | H31: - | I31: - | J31: 8 | K31: #9929 | L31: #9932 | M31: Codeテーブルから値を参照する必要があるため修正
A32: 31 | B32: - | C32: ハードウェア台帳 | D32: 保守 | E32: He | F32: 2 | G32: ハードウェア台帳保守 説明文の位置修正 | H32: - | I32: - | J32: 8 | K32: - | L32: - | M32: -
